<?xml version="1.0"?>
<robot name="titan" xmlns:xacro="http://ros.org/wiki/xacro">
<xacro:macro name="kuka_kr1000_titan" params="prefix">

    <!-- LINKS -->
    <!-- base link -->
    <link name="${prefix}base_link">
        <inertial>
            <origin xyz="0 0 0" rpy="0 0 0" />
            <mass value="1.0" />
            <inertia ixx="0.2" ixy="0" ixz="0" iyy="0.2" iyz="0" izz="0.2" />
        </inertial>
        <visual>
            <origin xyz="0 0 0" rpy="0 0 0"/>
            <geometry>
                <mesh filename="package://kuka_kr1000_titan_support/meshes/kr1000_titan/visual/base_link.stl"/>
            </geometry>
            <material name="visual_material">
                <color rgba="1 0.455 0 1"/>
            </material>
        </visual>
        <collision name="b_${prefix}base_link">
            <origin xyz="-0.225 0 0.275" rpy="0 0 0" />
            <geometry>
<!--                <mesh filename="package://kuka_kr1000_titan_support/meshes/kr1000_titan/collision/base_link.stl"/>-->
              <box size="1.75 1.3 0.55" />
            </geometry>
            <material name="collision_material">
                <color rgba="1 0.455 0 1"/>
            </material>
        </collision>
    </link>
    <!-- link 1 -->
    <link name="${prefix}link_1">
        <inertial>
            <origin xyz="0.2427 0.0251 0.4865" rpy="0 0 0" />
            <mass value="1.0" />
            <inertia ixx="0.2" ixy="0" ixz="0" iyy="0.2" iyz="0" izz="0.2" />
        </inertial>
        <visual>
            <origin xyz="0 0 0" rpy="0 0 0"/>
            <geometry>
                <mesh filename="package://kuka_kr1000_titan_support/meshes/kr1000_titan/visual/link_1.stl"/>
            </geometry>
            <material name="visual_material">
                <color rgba="1 0.455 0 1"/>
            </material>
        </visual>
        <collision name="b_${prefix}link_1">
            <origin xyz="0.055 0.13 0.55" rpy="0 0 0"/>
            <geometry>
<!--                <mesh filename="package://kuka_kr1000_titan_support/meshes/kr1000_titan/collision/link_1.stl"/>-->
              <box size="1.85 1.3 1.1" />
            </geometry>
            <material name="collision_material"/>
        </collision>
    </link>
    <!-- link 2 -->
    <link name="${prefix}link_2">
        <inertial>
            <origin xyz="0.0008 -0.1109 0.4051" rpy="0 0 0" />
            <mass value="1.0" />
            <inertia ixx="0.2" ixy="0" ixz="0" iyy="0.2" iyz="0" izz="0.04" />
        </inertial>
        <visual>
            <origin xyz="0 0 0" rpy="0 0 0"/>
            <geometry>
                <mesh filename="package://kuka_kr1000_titan_support/meshes/kr1000_titan/visual/link_2.stl"/>
            </geometry>
            <material name="visual_material">
                <color rgba="1 0.455 0 1"/>
            </material>
        </visual>
        <collision name="c_${prefix}link_2">
            <origin xyz="0 -0.15 0.75" rpy="0 0 0"/>
            <geometry>
<!--                <mesh filename="package://kuka_kr1000_titan_support/meshes/kr1000_titan/collision/link_2.stl"/>-->
              <cylinder radius="0.38" length="1.9" />
            </geometry>
            <material name="collision_material"/>
        </collision>
    </link>
    <!-- link 3 -->
    <link name="${prefix}link_3">
        <inertial>
            <origin xyz="-0.0220 0.3535 0.0397" rpy="0 0 0" />
            <mass value="1.0" />
            <inertia ixx="0.055" ixy="0" ixz="0" iyy="0.075" iyz="0" izz="0.075" />
        </inertial>
        <visual>
            <origin xyz="0 0 0" rpy="0 0 0"/>
            <geometry>
                <mesh filename="package://kuka_kr1000_titan_support/meshes/kr1000_titan/visual/link_3.stl"/>
            </geometry>
            <material name="visual_material">
                <color rgba="1 0.455 0 1"/>
            </material>
        </visual>
        <collision name="b_${prefix}link_3">
            <origin xyz="-0.15 0.5 0.05" rpy="0 0 0"/>
            <geometry>
<!--                <mesh filename="package://kuka_kr1000_titan_support/meshes/kr1000_titan/collision/link_3.stl"/>-->
              <box size="1.15 1.0 0.8" />
            </geometry>
            <material name="collision_material"/>
        </collision>
    </link>
    <!-- link 4 -->
    <link name="${prefix}link_4">
        <inertial>
            <origin xyz="0.3353 0.0090 0.0063" rpy="0 0 0" />
            <mass value="1.0" />
            <inertia ixx="0.025" ixy="0" ixz="0" iyy="0.05" iyz="0" izz="0.05" />
        </inertial>
        <visual>
            <origin xyz="0 0 0" rpy="0 0 0"/>
            <geometry>
                <mesh filename="package://kuka_kr1000_titan_support/meshes/kr1000_titan/visual/link_4.stl"/>
            </geometry>
            <material name="visual_material">
                <color rgba="1 0.455 0 1"/>
            </material>
        </visual>
        <collision name="c_${prefix}link_4">
            <origin xyz="0.48 0.025 0" rpy="0 1.57 0"/>
            <geometry>
<!--                <mesh filename="package://kuka_kr1000_titan_support/meshes/kr1000_titan/collision/link_4.stl"/>-->
              <cylinder radius="0.4" length="1.0" />
            </geometry>
            <material name="collision_material"/>
        </collision>
    </link>
    <!-- link 5 -->
    <link name="${prefix}link_5">
        <inertial>
            <origin xyz="0.0600 0.2479 -0.0008" rpy="0 0 0" />
            <mass value="1.0" />
            <inertia ixx="0.03" ixy="0" ixz="0" iyy="0.04" iyz="0" izz="0.04" />
        </inertial>
        <visual>
            <origin xyz="0 0 0" rpy="0 0 0"/>
            <geometry>
                <mesh filename="package://kuka_kr1000_titan_support/meshes/kr1000_titan/visual/link_5.stl"/>
            </geometry>
            <material name="visual_material">
                <color rgba="1 0.455 0 1"/>
            </material>
        </visual>
        <collision name="c_${prefix}link_5">
            <origin xyz="0.175 0.17 0" rpy="0 1.57 0"/>
            <geometry>
<!--                <mesh filename="package://kuka_kr1000_titan_support/meshes/kr1000_titan/collision/link_5.stl"/>-->
              <cylinder radius="0.2" length="0.35" />
            </geometry>
            <material name="collision_material"/>
        </collision>
    </link>
    <!-- link 6 -->
    <link name="${prefix}link_6">
        <inertial>
            <origin xyz="0.0117 0.0003 0.0002" rpy="0 0 0" />
            <mass value="1.0" />
            <inertia ixx="0.0075" ixy="0" ixz="0" iyy="0.003" iyz="0" izz="0.003" />
        </inertial>
        <visual>
            <origin xyz="0 0 0" rpy="0 0 0"/>
            <geometry>
                <mesh filename="package://kuka_kr1000_titan_support/meshes/kr1000_titan/visual/link_6.stl"/>
            </geometry>
            <material name="visual_material">
                <color rgba="1 0.455 0 1"/>
            </material>
        </visual>
        <collision name="c_${prefix}link_6">
            <origin xyz="0.015 0 0" rpy="0 1.57 0"/>
            <geometry>
<!--                <mesh filename="package://kuka_kr1000_titan_support/meshes/kr1000_titan/collision/link_6.stl"/>-->
              <cylinder radius="0.13" length="0.03" />
            </geometry>
            <material name="collision_material"/>
        </collision>
    </link>
    <!-- tool 0 -->
    <!-- This frame corresponds to the $FLANGE coordinate system in KUKA KRC controllers. -->
    <link name="${prefix}tool0"/>
    <!-- END LINKS -->

    <!-- JOINTS -->
    <!-- joint 1 (A1) -->
    <joint name="${prefix}joint_a1" type="revolute">
      <origin xyz="0 0 0.388623" rpy="0 0 0"/>
      <parent link="${prefix}base_link"/>
      <child link="${prefix}link_1"/>
      <axis xyz="0 0 -1"/>
      <limit effort="100.0" velocity="5.0" lower="-2.61799" upper="2.61799"/>
      <dynamics damping="1" friction="10"/>
    </joint>
    <!-- joint 2 (A2) -->
    <joint name="${prefix}joint_a2" type="revolute">
      <origin xyz="0.6 -0.094 0.74" rpy="0 1.57 0"/>
      <parent link="${prefix}link_1"/>
      <child link="${prefix}link_2"/>
      <axis xyz="0 1 0"/>
      <limit effort="100.0" velocity="5.0" lower="-2.26893" upper="0.3054326"/>
      <dynamics damping="1" friction="10"/>
    </joint>
    <!-- joint 3 (A3) -->
    <joint name="${prefix}joint_a3" type="revolute">
      <origin xyz="-0.000403 -0.2265 1.4" rpy="0 -1.57 0"/>
      <parent link="${prefix}link_2"/>
      <child link="${prefix}link_3"/>
      <axis xyz="0 1 0"/>
      <limit effort="100.0" velocity="5.0" lower="-1.91986" upper="2.53073"/>
      <dynamics damping="1" friction="10"/>
    </joint>
    <!-- joint 4 (A4) -->
    <joint name="${prefix}joint_a4" type="revolute">
      <origin xyz="0.431 0.32049 0.065004" rpy="0 0 0"/>
      <parent link="${prefix}link_3"/>
      <child link="${prefix}link_4"/>
      <axis xyz="-1 0 0"/>
      <limit effort="100.0" velocity="5.0" lower="-6.10865" upper="6.10865"/>
      <dynamics damping="1" friction="30"/>
    </joint>
    <!-- joint 5 (A5) -->
    <joint name="${prefix}joint_a5" type="revolute">
      <origin xyz="0.76907 -0.16378 0.015114" rpy="0 0 0"/>
      <parent link="${prefix}link_4"/>
      <child link="${prefix}link_5"/>
      <axis xyz="0 1 0"/>
      <limit effort="100.0" velocity="5.0" lower="-2.05949" upper="2.05949"/>
      <dynamics damping="1" friction="10"/>
    </joint>
    <!-- joint 6 (A6) -->
    <joint name="${prefix}joint_a6" type="revolute">
      <origin xyz="0.3448 0.16555 -0.00441" rpy="0 0 0"/>
      <parent link="${prefix}link_5"/>
      <child link="${prefix}link_6"/>
      <axis xyz="-1 0 0"/>
      <limit effort="100.0" velocity="5.0" lower="-6.10865" upper="6.10865"/>
      <dynamics damping="1" friction="30"/>
    </joint>
    <!-- tool frame - fixed frame -->
    <joint name="${prefix}joint_a6-tool0" type="fixed">
      <parent link="${prefix}link_6"/>
      <child link="${prefix}tool0"/>
      <origin xyz="0.025 0 0" rpy="0 ${radians(90)} 0"/>
    </joint>
    <!-- END JOINTS -->

    <!-- REVIEW -->
    <!-- ROS base_link to Robot Manufacturer World Coordinates transform -->
    <link name="${prefix}base" />
    <joint name="${prefix}base_link-base" type="fixed">
        <origin xyz="0 0 0" rpy="0 0 0"/>
        <parent link="${prefix}base_link"/>
        <child link="${prefix}base"/>
    </joint>

</xacro:macro>
</robot>
